<?xml version="0.0"?>
<robot name="simple__arm">

  <!-- BASE LINK -->
  <link name="base_link">
    <inertial>
      <origin xyz="0 0 0.05"/>
      <mass value="0.5"/>
      <inertia ixx="0.001" iyy="0.001" izz="0.001" ixy="0" ixz="0" iyz="0"/>
    </inertial>
    <visual>
      <origin xyz="0 0 0.05"/>
      <geometry>
        <cylinder length="0.1" radius="0.03"/>
      </geometry>
      <material name="gray">
        <color rgba="0.6 0.6 0.6 1"/>
      </material>
    </visual>
    <collision>
      <origin xyz="0 0 0.05"/>
      <geometry>
        <cylinder length="0.1" radius="0.03"/>
      </geometry>
    </collision>
  </link>

  <!-- JOINT 1 -->
  <joint name="joint1" type="continuous">
    <parent link="base_link"/>
    <child link="link1"/>
    <origin xyz="0 0 0.10"/>
    <axis xyz="0 0 1"/>
    <dynamics damping="0.1" friction="0.0"/>
  </joint>

  <!-- LINK 1 -->
  <link name="link1">
    <inertial>
      <origin xyz="0 0 0.025"/>
      <mass value="0.3"/>
      <inertia ixx="0.0005" iyy="0.0005" izz="0.0005" ixy="0" ixz="0" iyz="0"/>
    </inertial>
    <visual>
      <origin xyz="0 0 0.025"/>
      <geometry>
        <cylinder length="0.05" radius="0.025"/>
      </geometry>
      <material name="blue">
        <color rgba="0 0 0.8 1"/>
      </material>
    </visual>
    <collision>
      <origin xyz="0 0 0.025"/>
      <geometry>
        <cylinder length="0.05" radius="0.025"/>
      </geometry>
    </collision>
  </link>

  <!-- JOINT 2 -->
  <joint name="joint2" type="continuous">
    <parent link="link1"/>
    <child link="link2"/>
    <origin xyz="0 0 0.05"/>
    <axis xyz="0 1 0"/>
    <dynamics damping="0.1" friction="0.0"/>
  </joint>

  <!-- LINK 2 -->
  <link name="link2">
    <inertial>
      <origin xyz="0 0 0.075"/>
      <mass value="0.2"/>
      <inertia ixx="0.0004" iyy="0.0004" izz="0.0004" ixy="0" ixz="0" iyz="0"/>
    </inertial>
    <visual>
      <origin xyz="0 0 0.075"/>
      <geometry>
        <cylinder length="0.15" radius="0.02"/>
      </geometry>
      <material name="green">
        <color rgba="0 0.8 0 1"/>
      </material>
    </visual>
    <collision>
      <origin xyz="0 0 0.075"/>
      <geometry>
        <cylinder length="0.15" radius="0.02"/>
      </geometry>
    </collision>
  </link>

  <!-- JOINT 3 -->
  <joint name="joint3" type="continuous">
    <parent link="link2"/>
    <child link="link3"/>
    <origin xyz="0 0 0.15"/>
    <axis xyz="0 1 0"/>
    <dynamics damping="0.1" friction="0.0"/>
  </joint>

  <!-- LINK 3 -->
  <link name="link3">
    <inertial>
      <origin xyz="0 0 0.075"/>
      <mass value="0.1"/>
      <inertia ixx="0.0003" iyy="0.0003" izz="0.0003" ixy="0" ixz="0" iyz="0"/>
    </inertial>
    <visual>
      <origin xyz="0 0 0.075"/>
      <geometry>
        <cylinder length="0.15" radius="0.01"/>
      </geometry>
      <material name="red">
        <color rgba="0.8 0 0 1"/>
      </material>
    </visual>
    <collision>
      <origin xyz="0 0 0.075"/>
      <geometry>
        <cylinder length="0.15" radius="0.01"/>
      </geometry>
    </collision>
  </link>

  <!-- JOINT 4: fixed joint for end effector -->
<joint name="joint4" type="fixed">
  <parent link="link3"/>
  <child link="tool_link"/>
  <origin xyz="0 0 0.15"/> <!-- offset along link3 length -->
  <axis xyz="0 0 0"/>
</joint>

<!-- LINK tool_link: small invisible or visual tip -->
<link name="tool_link">
  <inertial>
    <origin xyz="0 0 0"/>
    <mass value="0.01"/>
    <inertia ixx="0.00001" iyy="0.00001" izz="0.00001" ixy="0" ixz="0" iyz="0"/>
  </inertial>
  <visual>
    <origin xyz="0 0 0"/>
    <geometry>
      <sphere radius="0.005"/>
    </geometry>
    <material name="yellow">
      <color rgba="1 1 0 1"/>
    </material>
  </visual>
  <collision>
    <origin xyz="0 0 0"/>
    <geometry>
      <sphere radius="0.005"/>
    </geometry>
  </collision>
</link>


</robot>
